<mujoco model="tocabi">
  <compiler angle="radian" meshdir="meshes"/>

  <asset>
    <mesh name="Pelvis_link"        file="Pelvis_link2.STL"     scale="0.001 0.001 0.001"/>
    <mesh name="HipRoll_L_Link"     file="HipRoll_L_Link.STL"/>
    <mesh name="HipCenter_L_Link"   file="HipCenter_L_Link.STL"/>
    <mesh name="Thigh_L_Link"       file="Thigh_L_Link.STL"/>
    <mesh name="Knee_L_Link"        file="Knee_L_Link.STL"/>
    <mesh name="AnkleCenter_L_Link" file="AnkleCenter_L_Link.STL"/>
    <mesh name="AnkleRoll_L_Link"   file="AnkleRoll_L_Link.STL"/>
    <mesh name="Foot_Link"          file="Foot_Link.STL"/>
    <mesh name="HipRoll_R_link"     file="HipRoll_R_link.STL"/>
    <mesh name="HipCenter_R_Link"   file="HipCenter_R_Link.STL"/>
    <mesh name="Thigh_R_Link"       file="Thigh_R_Link.STL"/>
    <mesh name="Knee_R_Link"        file="Knee_R_Link.STL"/>
    <mesh name="AnkleCenter_R_Link" file="AnkleCenter_R_Link.STL"/>
    <mesh name="AnkleRoll_R_Link"   file="AnkleRoll_R_Link.STL"/>
    <mesh name="waist1"             file="waistyaw.STL"         scale="0.001 0.001 0.001"/>
    <mesh name="waist2"             file="waist2.STL"/>
    <mesh name="upperbody"          file="upperbody.STL"/>
    <mesh name="L_shoulder1"        file="L_shoulder1.STL"/>
    <mesh name="L_shoulder2"        file="L_shoulder2.STL"/>
    <mesh name="L_shoulder3"        file="L_shoulder3.STL"/>
    <mesh name="L_arm"              file="L_arm.STL"/>
    <mesh name="L_elbow"            file="L_elbow.STL"/>
    <mesh name="L_forearm"          file="L_forearm.STL"/>
    <mesh name="L_wrist1"           file="L_wrist1.STL"/>
    <mesh name="L_wrist2"           file="L_wrist2.STL"/>
    <mesh name="neck"               file="neck.STL"/>
    <mesh name="head_mesh"          file="head.STL"             scale="0.001 0.001 0.001"/>
    <mesh name="R_shoulder1"        file="R_shoulder1.STL"/>
    <mesh name="R_shoulder2"        file="R_shoulder2.STL"/>
    <mesh name="R_shoulder3"        file="R_shoulder3.STL"/>
    <mesh name="R_arm"              file="R_arm.STL"/>
    <mesh name="R_elbow"            file="R_elbow.STL"/>
    <mesh name="R_forearm"          file="R_forearm.STL"/>
    <mesh name="R_wrist1"           file="R_wrist1.STL"/>
    <mesh name="R_wrist2"           file="R_wrist2.STL"/>
  </asset>

  <default>
    <motor ctrlrange="-1 1" ctrllimited="true"/>
    <default class="body">
      <geom condim="1" friction="1.0 0.05 0.05"
            solimp=".9 .99 .003" solref=".015 1"/>
      <joint limited="true" solimplimit="0 .99 .01"/>
    </default>
  </default>

  <!-- Joint order: L leg(6) R leg(6) Torso(3) L arm(8) Head(2) R arm(8) = 33 DOF -->
  <worldbody>
    <body name="base_link" pos="0 0 0" childclass="body">
      <freejoint name="root"/>
      <inertial pos="0.07809 0 0.03985" mass="12.19525"
                fullinertia="0.101833182 0.072400662 0.144478157 -0.000070812 -0.003831096 0.000079272"/>
      <geom type="mesh" mesh="Pelvis_link" rgba="0.20313 0.20313 0.20313 1" pos="0.11 0 0.02" quat="0.5 0.5 0.5 0.5" contype="0" conaffinity="0"/>
      <geom name="pelvis_col" type="box" pos="0.052 0 0.02" size="0.12 0.1525 0.025"/>

      <!-- ==================== LEFT LEG ================================ -->
      <body name="L_HipRoll_Link" pos="0.11 0.1025 -0.1025">
        <inertial pos="-0.06477 0 0.05149" mass="2.679"
                  fullinertia="0.01821 0.03121 0.2928 -1.676E-07 -0.0007745 -4.53E-09"/>
        <joint name="L_HipYaw_Joint" type="hinge" axis="0 0 1"
               range="-3.14 3.14" stiffness="222.2222" damping="5.0000" armature="0.6140"/>
        <geom type="mesh" mesh="HipRoll_L_Link" rgba="0.20313 0.20313 0.20313 1" contype="0" conaffinity="0"/>
        <geom type="cylinder" size="0.045 0.04" pos="-0.1 0 0" quat="0.707107 0 0.707107 0"/>

        <body name="L_HipCenter_Link" pos="0 0 0">
          <inertial pos="-0.04801 0.0022 2e-05" mass="2.67"
                    fullinertia="0.3553 0.009161 0.00876 1.725E-08 -3.236E-06 -4.778E-06"/>
          <joint name="L_HipRoll_Joint" type="hinge" axis="1 0 0"
                 range="-3.14 3.14" stiffness="555.5556" damping="16.6667" armature="0.8620"/>
          <geom type="mesh" mesh="HipCenter_L_Link" rgba="0.20313 0.20313 0.20313 1" contype="0" conaffinity="0"/>
          <geom type="box" size="0.05225 0.03 0.0475" pos="-0.0045 0 0"/>

          <body name="L_Thigh_Link" pos="0 0 0">
            <inertial pos="-0.00042 0.00032 -0.18904" mass="5.366"
                      fullinertia="0.2987 0.7088 0.00982 -4.284E-05 -0.000196 0.002406"/>
            <joint name="L_HipPitch_Joint" type="hinge" axis="0 1 0"
                   range="-3.14 3.14" stiffness="444.4444" damping="6.6667" armature="1.0900"/>
            <geom type="mesh" mesh="Thigh_L_Link" rgba="0.85938 0.07813 0.23438 1" contype="0" conaffinity="0"/>
            <geom type="cylinder" size="0.06 0.10875" pos="0 0 -0.1923"/>

            <body name="L_Knee_Link" pos="0 0 -0.35">
              <inertial pos="0.00429 -0.00214 -0.1428" mass="3.883"
                        fullinertia="0.1506 0.5588 0.007451 -2.887E-05 -0.002607 -0.001486"/>
              <joint name="L_Knee_Joint" type="hinge" axis="0 1 0"
                     range="-3.14 3.14" stiffness="411.1111" damping="8.3333" armature="1.0900"/>
              <geom type="mesh" mesh="Knee_L_Link" rgba="0.85938 0.07813 0.23438 1" contype="0" conaffinity="0"/>
              <geom type="cylinder" size="0.06 0.1" pos="0 0 -0.175"/>

              <body name="L_AnkleCenter_Link" pos="0 0 -0.35">
                <inertial pos="-0.00419 0.0018 -0.0003" mass="2.51"
                          fullinertia="0.002857 0.4135 0.003345 -1.422E-07 2.222E-06 4.611E-06"/>
                <joint name="L_AnklePitch_Joint" type="hinge" axis="0 1 0"
                       range="-3.14 3.14" stiffness="355.5556" damping="8.0000" armature="1.0900"/>
                <geom type="mesh" mesh="AnkleCenter_L_Link" rgba="0.20313 0.20313 0.20313 1" contype="0" conaffinity="0"/>
                <geom type="box" size="0.05225 0.03 0.0475" pos="-0.0045 0 0"/>

                <body name="L_AnkleRoll_Link" pos="0 0 0">
                  <inertial pos="-0.05196 0.00005 -0.0219" mass="1.26426"
                            fullinertia="0.418697 0.006211405 0.008575514 1.5176E-08 -0.001095976 -5.435E-08"/>
                  <joint name="L_AnkleRoll_Joint" type="hinge" axis="1 0 0"
                         range="-3.14 3.14" stiffness="355.5556" damping="8.0000" armature="0.3600"/>
                  <geom type="mesh" mesh="AnkleRoll_L_Link" rgba="0.85938 0.07813 0.23438 1" contype="0" conaffinity="0"/>
                  <body name="left_foot" pos="0 0 0">
                    <inertial pos="0.0162 8e-05 -0.1209" mass="2.326"
                              fullinertia="0.003386409 0.012600125 0.014296 1.1237E-05 -0.000526477 -1.976E-06"/>
                    <geom type="mesh" mesh="Foot_Link" rgba="0.85938 0.07813 0.23438 1" contype="0" conaffinity="0"/>
                    <geom name="left_foot" type="box" pos="0.03 0 -0.145" size="0.15 0.065 0.0135"/>
                  </body>
                </body>
              </body>
            </body>
          </body>
        </body>
      </body>

      <!-- ==================== RIGHT LEG =============================== -->
      <body name="R_HipRoll_Link" pos="0.11 -0.1025 -0.1025">
        <inertial pos="-0.06477 0 0.05149" mass="2.679"
                  fullinertia="0.01821 0.03121 0.2928 -1.676E-07 -0.0007745 -4.53E-09"/>
        <joint name="R_HipYaw_Joint" type="hinge" axis="0 0 1"
               range="-3.14 3.14" stiffness="222.2222" damping="5.0000" armature="0.6140"/>
        <geom type="mesh" mesh="HipRoll_R_link" rgba="0.20313 0.20313 0.20313 1" contype="0" conaffinity="0"/>
        <geom type="cylinder" size="0.045 0.04" pos="-0.1 0 0" quat="0.707107 0 0.707107 0"/>

        <body name="R_HipCenter_Link" pos="0 0 0">
          <inertial pos="-0.04801 -0.0022 2e-05" mass="2.67"
                    fullinertia="0.3553 0.009161 0.00876 1.725E-08 -3.236E-06 -4.778E-06"/>
          <joint name="R_HipRoll_Joint" type="hinge" axis="1 0 0"
                 range="-3.14 3.14" stiffness="555.5556" damping="16.6667" armature="0.8620"/>
          <geom type="mesh" mesh="HipCenter_R_Link" rgba="0.20313 0.20313 0.20313 1" contype="0" conaffinity="0"/>
          <geom type="box" size="0.05225 0.03 0.0475" pos="-0.0045 0 0"/>

          <body name="R_Thigh_Link" pos="0 0 0">
            <inertial pos="-0.00042 -0.00032 -0.18904" mass="5.366"
                      fullinertia="0.2987 0.7088 0.00982 -4.284E-05 -0.000196 0.002406"/>
            <joint name="R_HipPitch_Joint" type="hinge" axis="0 1 0"
                   range="-3.14 3.14" stiffness="444.4444" damping="6.6667" armature="1.0900"/>
            <geom type="mesh" mesh="Thigh_R_Link" rgba="0.85938 0.07813 0.23438 1" contype="0" conaffinity="0"/>
            <geom type="cylinder" size="0.06 0.10875" pos="0 0 -0.1923"/>

            <body name="R_Knee_Link" pos="0 0 -0.35">
              <inertial pos="0.00429 0.00214 -0.1428" mass="3.883"
                        fullinertia="0.1506 0.5588 0.007451 -2.887E-05 -0.002607 -0.001486"/>
              <joint name="R_Knee_Joint" type="hinge" axis="0 1 0"
                     range="-3.14 3.14" stiffness="411.1111" damping="8.3333" armature="1.0900"/>
              <geom type="mesh" mesh="Knee_R_Link" rgba="0.85938 0.07813 0.23438 1" contype="0" conaffinity="0"/>
              <geom type="cylinder" size="0.06 0.1" pos="0 0 -0.175"/>

              <body name="R_AnkleCenter_Link" pos="0 0 -0.35">
                <inertial pos="-0.00419 -0.0018 -0.0003" mass="2.51"
                          fullinertia="0.002857 0.4135 0.003345 -1.422E-07 2.222E-06 4.611E-06"/>
                <joint name="R_AnklePitch_Joint" type="hinge" axis="0 1 0"
                       range="-3.14 3.14" stiffness="355.5556" damping="8.0000" armature="1.0900"/>
                <geom type="mesh" mesh="AnkleCenter_R_Link" rgba="0.20313 0.20313 0.20313 1" contype="0" conaffinity="0"/>
                <geom type="box" size="0.05225 0.03 0.0475" pos="-0.0045 0 0"/>

                <body name="R_AnkleRoll_Link" pos="0 0 0">
                  <inertial pos="-0.05196 0.00005 -0.0219" mass="1.26426"
                            fullinertia="0.418697 0.006211405 0.008575514 1.5176E-08 -0.001095976 -5.435E-08"/>
                  <joint name="R_AnkleRoll_Joint" type="hinge" axis="1 0 0"
                         range="-3.14 3.14" stiffness="355.5556" damping="8.0000" armature="0.3600"/>
                  <geom type="mesh" mesh="AnkleRoll_R_Link" rgba="0.85938 0.07813 0.23438 1" contype="0" conaffinity="0"/>
                  <body name="right_foot" pos="0 0 0">
                    <inertial pos="0.0162 8e-05 -0.1209" mass="2.326"
                              fullinertia="0.003386409 0.012600125 0.014296 1.1237E-05 -0.000526477 -1.976E-06"/>
                    <geom type="mesh" mesh="Foot_Link" rgba="0.85938 0.07813 0.23438 1" contype="0" conaffinity="0"/>
                    <geom name="right_foot" type="box" pos="0.03 0 -0.145" size="0.15 0.065 0.0135"/>
                  </body>
                </body>
              </body>
            </body>
          </body>
        </body>
      </body>

      <!-- ==================== TORSO =================================== -->
      <body name="Waist1_Link" pos="0.11 0 0.1979">
        <inertial pos="0 0 -0.03647" mass="0.89722"
                  fullinertia="0.003744227 0.002030963 1.007723743 -0.000023489 0.000037149 -0.000424890"/>
        <geom type="mesh" mesh="waist1" rgba="0.85938 0.07813 0.23438 1" pos="0 0 -0.085" quat="0 0.707107 0 0.707107" contype="0" conaffinity="0"/>
        <geom type="cylinder" size="0.05 0.01" pos="0 0 -0.096"/>

        <body name="Waist2_Link" pos="0 0 0">
          <inertial pos="-0.00029 0 0" mass="3.752"
                    fullinertia="0.006020606 1.011708561 0.007561688 0.000011504 -0.000000053 0.000001147"/>
          <geom type="mesh" mesh="waist2" rgba="0.20313 0.20313 0.20313 1" contype="0" conaffinity="0"/>
          <geom type="cylinder" size="0.055 0.05" quat="0.707107 0.707107 0 0"/>

          <body name="Upperbody_Link" pos="0 0 0">
            <inertial pos="-0.07294 0 0.16798" quat="0.999909 -0.000268355 -0.0135223 5.11667e-05"
                      mass="18.1338" diaginertia="0.563198 0.563198 0.563198"/>
            <geom type="mesh" mesh="upperbody" rgba="0.85938 0.07813 0.23438 1" contype="0" conaffinity="0"/>
            <geom type="box" pos="-0.03 0 0.200" size="0.105 0.110 0.050"/>
            <geom type="box" pos="-0.03 0 0.115" size="0.105 0.055 0.035"/>

            <!-- =============== LEFT ARM ============================== -->
            <body name="L_Shoulder1_Link" pos="0.023 0.154 0.2275">
              <inertial pos="-3e-05 0.00397 0.06029" mass="1.6762"
                        fullinertia="0.001925606 0.001936576 0.185330098 0.000001433 0.000002313 0.000078962"/>
              <geom type="mesh" mesh="L_shoulder1" rgba="0.85938 0.07813 0.23438 1" contype="0" conaffinity="0"/>
              <geom type="cylinder" size="0.04 0.055" pos="0 0 0.05"/>

              <body name="L_Shoulder2_Link" pos="0 0.0341 0.065">
                <inertial pos="0.00107 0.0491 -1e-05" mass="0.4016"
                          fullinertia="0.000989903 0.184275853 0.001067575 0.000028237 -0.000000465 0.000000133"/>
                <geom type="mesh" mesh="L_shoulder2" rgba="0.20313 0.20313 0.20313 1" contype="0" conaffinity="0"/>
                <geom type="cylinder" size="0.04 0.025" pos="0 0.04 0" quat="0.707107 0.707107 0 0"/>

                <body name="L_Shoulder3_Link" pos="0 0.115 0">
                  <inertial pos="0.00262 0.04826 0.00023" mass="2.90141"
                            fullinertia="0.192093159 0.002493784 0.008296854 -0.000365084 -0.000002746 -0.000023821"/>
                  <geom type="mesh" mesh="L_shoulder3" rgba="0.20313 0.20313 0.20313 1" contype="0" conaffinity="0"/>
                  <geom type="cylinder" size="0.04 0.06" pos="0 0.06 0" quat="0.707107 0.707107 0 0"/>

                  <body name="L_Armlink_Link" pos="0 0.1281 0">
                    <inertial pos="-0.01896 0.11642 -0.0119" mass="0.58517"
                              fullinertia="0.002878609 0.184381923 0.003117058 0.000302586 -0.000036001 0.000398377"/>
                    <geom type="mesh" mesh="L_arm" rgba="0.85938 0.07813 0.23438 1" contype="0" conaffinity="0"/>
                    <geom type="cylinder" size="0.04 0.08" pos="0 0.08 0" quat="0.707107 0.707107 0 0"/>

                    <body name="L_Elbow_Link" pos="0 0.207 -0.0325">
                      <inertial pos="-0.00136 0.05256 0.01764" mass="2.06511"
                                fullinertia="0.055865466 0.001895543 0.005958821 0.000151764 0.000055158 0.001530917"/>
                      <geom type="mesh" mesh="L_elbow" rgba="0.20313 0.20313 0.20313 1" contype="0" conaffinity="0"/>
                      <geom type="cylinder" size="0.04 0.04" pos="0 0.08 0.0325" quat="0.707107 0.707107 0 0"/>

                      <body name="L_Forearm_Link" pos="0 0.1244 0.0325">
                        <inertial pos="-0.01426 0.0767 0.00033" mass="0.35234"
                                  fullinertia="0.001053636 0.049889479 0.001266418 0.000084568 0.000022117 0.000019539"/>
                        <geom type="mesh" mesh="L_forearm" rgba="0.85938 0.07813 0.23438 1" contype="0" conaffinity="0"/>
                        <geom type="cylinder" size="0.04 0.05" pos="0 0.05 0" quat="0.707107 0.707107 0 0"/>

                        <body name="L_Wrist1_Link" pos="0 0.1451 0">
                          <inertial pos="-0.00158 0.02153 3e-05" mass="0.70923"
                                    fullinertia="0.015205197 0.000396376 0.000683187 0.000024218 -0.000000263 0.000000688"/>
                          <geom type="mesh" mesh="L_wrist1" rgba="0.20313 0.20313 0.20313 1" contype="0" conaffinity="0"/>
                          <geom type="cylinder" size="0.02 0.03" pos="0 0.046 0"/>

                          <body name="left_hand" pos="0 0.046 0">
                            <inertial pos="0.00063 0.0636 0.00178" mass="0.1"
                                      fullinertia="0.000865450 0.000696917 0.015377823 0 0 0"/>
                            <geom type="mesh" mesh="L_wrist2" rgba="0.20313 0.20313 0.20313 1" contype="0" conaffinity="0"/>
                            <geom name="left_hand" type="box" pos="0 0 -0.025" size="0.03 0.03 0.01"/>
                          </body>
                        </body>
                      </body>
                    </body>
                  </body>
                </body>
              </body>
            </body>

            <!-- =============== HEAD ================================== -->
            <body name="Neck_Link" pos="-0.036 0 0.3795">
              <inertial pos="0 0 -0.0023" mass="0.248"
                        fullinertia="0.000058259 0.000036489 0.000058237 -0.000000076 0.000000268 -0.000001002"/>
              <geom type="mesh" mesh="neck" rgba="0.20313 0.20313 0.20313 1" contype="0" conaffinity="0"/>

              <body name="head" pos="0 0 0.0275">
                <inertial pos="0.037 0 0.071" mass="1.417"
                          fullinertia="0.0079 0.012 0.01 0.0 0.0025 0.0"/>
                <geom type="mesh" mesh="head_mesh" rgba="0.85938 0.07813 0.23438 1" pos="0.02 0 -0.6" contype="0" conaffinity="0"/>
                <geom name="head" type="box" pos="0.02 0 0.14" size="0.08 0.06 0.086"/>
              </body>
            </body>

            <!-- =============== RIGHT ARM ============================= -->
            <body name="R_Shoulder1_Link" pos="0.023 -0.154 0.2275">
              <inertial pos="-3e-05 -0.00397 0.06029" mass="1.6762"
                        fullinertia="0.001925606 0.001936576 0.185330098 -0.000001433 0.000002313 -0.000078962"/>
              <geom type="mesh" mesh="R_shoulder1" rgba="0.85938 0.07813 0.23438 1" contype="0" conaffinity="0"/>
              <geom type="cylinder" size="0.04 0.055" pos="0 0 0.05"/>

              <body name="R_Shoulder2_Link" pos="0 -0.0341 0.065">
                <inertial pos="0.00107 -0.0491 -1e-05" mass="0.4016"
                          fullinertia="0.000989903 0.184275853 0.001067575 -0.000028237 -0.000000465 -0.000000133"/>
                <geom type="mesh" mesh="R_shoulder2" rgba="0.20313 0.20313 0.20313 1" contype="0" conaffinity="0"/>
                <geom type="cylinder" size="0.04 0.025" pos="0 -0.04 0" quat="0.707107 0.707107 0 0"/>

                <body name="R_Shoulder3_Link" pos="0 -0.115 0">
                  <inertial pos="0.00262 -0.04826 0.00023" mass="2.90141"
                            fullinertia="0.192093159 0.002493784 0.008296854 0.000365084 -0.000002746 0.000023821"/>
                  <geom type="mesh" mesh="R_shoulder3" rgba="0.20313 0.20313 0.20313 1" contype="0" conaffinity="0"/>
                  <geom type="cylinder" size="0.04 0.06" pos="0 -0.06 0" quat="0.707107 0.707107 0 0"/>

                  <body name="R_Armlink_Link" pos="0 -0.1281 0">
                    <inertial pos="-0.01896 -0.11642 -0.0119" mass="0.58517"
                              fullinertia="0.002878609 0.184381923 0.003117058 -0.000302586 -0.000036001 -0.000398377"/>
                    <geom type="mesh" mesh="R_arm" rgba="0.85938 0.07813 0.23438 1" contype="0" conaffinity="0"/>
                    <geom type="cylinder" size="0.04 0.08" pos="0 -0.08 0" quat="0.707107 0.707107 0 0"/>

                    <body name="R_Elbow_Link" pos="0 -0.207 -0.0325">
                      <inertial pos="-0.00136 -0.05256 0.01764" mass="2.06511"
                                fullinertia="0.055865466 0.001895543 0.005958821 -0.000151764 0.000055158 -0.001530917"/>
                      <geom type="mesh" mesh="R_elbow" rgba="0.20313 0.20313 0.20313 1" contype="0" conaffinity="0"/>
                      <geom type="cylinder" size="0.04 0.04" pos="0 -0.08 0.0325" quat="0.707107 0.707107 0 0"/>

                      <body name="R_Forearm_Link" pos="0 -0.1244 0.0325">
                        <inertial pos="-0.01426 -0.0767 0.00033" mass="0.35234"
                                  fullinertia="0.001053636 0.049889479 0.001266418 -0.000084568 0.000022117 -0.000019539"/>
                        <geom type="mesh" mesh="R_forearm" rgba="0.85938 0.07813 0.23438 1" contype="0" conaffinity="0"/>
                        <geom type="cylinder" size="0.04 0.05" pos="0 -0.05 0" quat="0.707107 0.707107 0 0"/>

                        <body name="R_Wrist1_Link" pos="0 -0.1451 0">
                          <inertial pos="-0.00158 -0.02153 3e-05" mass="0.70923"
                                    fullinertia="0.015205197 0.000396376 0.000683187 -0.000024218 -0.000000263 -0.000000688"/>
                          <geom type="mesh" mesh="R_wrist1" rgba="0.20313 0.20313 0.20313 1" contype="0" conaffinity="0"/>
                          <geom type="cylinder" size="0.02 0.03" pos="0 -0.046 0"/>

                          <body name="right_hand" pos="0 -0.046 0">
                            <inertial pos="0.00063 -0.0636 0.00178" mass="0.1"
                                      fullinertia="0.000865450 0.000696917 0.015377823 0 0 0"/>
                            <geom type="mesh" mesh="R_wrist2" rgba="0.20313 0.20313 0.20313 1" contype="0" conaffinity="0"/>
                            <geom name="right_hand" type="box" pos="0 0 -0.025" size="0.03 0.03 0.01"/>
                          </body>
                        </body>
                      </body>
                    </body>
                  </body>
                </body>
              </body>
            </body>

          </body><!-- Upperbody_Link -->
        </body><!-- Waist2_Link -->
      </body><!-- Waist1_Link -->

    </body><!-- base_link -->
  </worldbody>

  <actuator>
    <motor name="L_HipYaw_Motor"     gear="100" joint="L_HipYaw_Joint"/>
    <motor name="L_HipRoll_Motor"    gear="100" joint="L_HipRoll_Joint"/>
    <motor name="L_HipPitch_Motor"   gear="100" joint="L_HipPitch_Joint"/>
    <motor name="L_Knee_Motor"       gear="100" joint="L_Knee_Joint"/>
    <motor name="L_AnklePitch_Motor" gear="100" joint="L_AnklePitch_Joint"/>
    <motor name="L_AnkleRoll_Motor"  gear="100" joint="L_AnkleRoll_Joint"/>
    <motor name="R_HipYaw_Motor"     gear="100" joint="R_HipYaw_Joint"/>
    <motor name="R_HipRoll_Motor"    gear="100" joint="R_HipRoll_Joint"/>
    <motor name="R_HipPitch_Motor"   gear="100" joint="R_HipPitch_Joint"/>
    <motor name="R_Knee_Motor"       gear="100" joint="R_Knee_Joint"/>
    <motor name="R_AnklePitch_Motor" gear="100" joint="R_AnklePitch_Joint"/>
    <motor name="R_AnkleRoll_Motor"  gear="100" joint="R_AnkleRoll_Joint"/>
  </actuator>

  <keyframe>
    <key name="stand"
         qpos="0 0 0.77003  1 0 0 0
               0.0   0.0  -0.24   0.6  -0.36   0.0
               0.0   0.0  -0.24   0.6  -0.36   0.0
               0.0   0.0   0.0
               0.3   0.3   1.5  -1.27  -1.0    0.0  -1.0   0.0
               0.0   0.0
              -0.3  -0.3  -1.5   1.27   1.0    0.0   1.0   0.0"/>
  </keyframe>

</mujoco>